Workbook

Sheet Loans
A1: Dinio Capital | Loan Tracker
A2: Blue text = you type it. Black text = formula. Grey fill = calculated column (do not type over it). Costo de Equipo is the base for all three fees.
A3: Loans 1 to 3 are SAMPLES (placeholder names, assumed dates, 8.99% and 60 months where not given). Replace them with real loans.
B4: Fee Rates | E4: Notes / Open Items
B5: Origination Fee % | C5: 0.01 | E5: 1. SAMPLE DATA: loans 1 to 3 are placeholders. Replace client names, dates, rates and terms with real values. 2. OPEN: the bank's invoice requirements are unknown (Bill To, Invoice #, payment instructions, layout). Confirm them. 3. OPEN: confirm the referral fee method and base against the agreement (modeled as the interest of a separate loan on Costo de Equipo, same term, at the yearly rate in the Fee Rates box). 4. First Payment Date defaults to 1 month after Closing Date. Type over it if the real date differs.
B6: Legal/Closing Fee % | C6: 0.01
B7: Referral Fee % (yearly) | C7: 0.005
B8: Today (automatic) | C8: =TODAY() -> 46296
A10: INPUTS (type in blue cells) | J10: CALCULATED | S10: HELPER COLUMNS (feed other tabs, do not edit)
A11: Loan # | B11: Client or Company | C11: Status | D11: Closing Date (expected if Pipeline) | E11: First Payment Date (auto, can overwrite) | F11: Costo de Equipo | G11: Pronto % | H11: Interes | I11: Termino (mo.) | J11: Pronto $ | K11: Monto a Financiar | L11: Pago Mensual | M11: Origination Fee | N11: Legal/Closing Fee | O11: Referral Fee over life of loan | P11: Referral Fee earned to date | Q11: Payments Made | R11: Next Payment Date | S11: Months from 1st Pmt to Today | T11: Payments Due to Date (uncapped) | U11: Closing Month | V11: Closing Fees (Orig + Legal) | W11: Closing Fees if Closed | X11: Closing Fees if Pipeline | Y11: Pipeline Counter
A12: 1 | B12: SAMPLE Client A (replace) | C12: Closed | D12: 46218 | E12: =IF(D12="","",EDATE(D12,1)) -> 46249 | F12: 38127.43 | G12: 0 | H12: 0.0899 | I12: 60 | J12: =IF(F12="","",F12*G12) -> 0 | K12: =IF(F12="","",F12-J12) -> 38127.43 | L12: =IF(OR(K12="",I12=""),"",PMT(H12/12,I12,-K12)) -> 791.2777 | M12: =IF(F12="","",IF(C12="Dead",0,F12*C5)) -> 381.2743 | N12: =IF(F12="","",IF(C12="Dead",0,F12*C6)) -> 381.2743 | O12: =IF(OR(F12="",I12=""),"",IF(C12="Dead",0,I12*PMT(C7/12,I12,-F12)-F12)) -> 486.52091 | P12: =IF(F12="","",IF(C12<>"Closed",0,SUMIF('Referral Fees'!I11:BP11,"<="&Q12,'Referral Fees'!I12:BP12))) -> 31.511325 | Q12: =IF(F12="","",IF(C12<>"Closed",0,IF(T12="",0,IF(T12<=0,0,IF(T12>I12,I12,T12))))) -> 2 | R12: =IF(C12<>"Closed","",IF(OR(E12="",I12=""),"",IF(Q12>=I12,"Paid off",EDATE(E12,Q12)))) -> 46310 | S12: =IF(OR(F12="",E12=""),"",(YEAR(C8)-YEAR(E12))*12+MONTH(C8)-MONTH(E12)) -> 2 | T12: =IF(S12="","",S12+IF(EDATE(E12,S12)<=C8,1,0)) -> 2 | U12: =IF(D12="","",DATE(YEAR(D12),MONTH(D12),1)) -> 46204 | V12: =IF(F12="","",M12+N12) -> 762.5486 | W12: =IF(C12="Closed",SUM(V12),0) -> 762.5486 | X12: =IF(C12="Pipeline",SUM(V12),0) -> 0 | Y12: =IF(C12="Pipeline",COUNTIF(C12:C12,"Pipeline"),"")
A13: 2 | B13: SAMPLE Client B (replace) | C13: Pipeline | D13: 46341 | E13: =IF(D13="","",EDATE(D13,1)) -> 46371 | F13: 58000 | G13: 0 | H13: 0.0899 | I13: 60 | J13: =IF(F13="","",F13*G13) -> 0 | K13: =IF(F13="","",F13-J13) -> 58000 | L13: =IF(OR(K13="",I13=""),"",PMT(H13/12,I13,-K13)) -> 1203.7031 | M13: =IF(F13="","",IF(C13="Dead",0,F13*C5)) -> 580 | N13: =IF(F13="","",IF(C13="Dead",0,F13*C6)) -> 580 | O13: =IF(OR(F13="",I13=""),"",IF(C13="Dead",0,I13*PMT(C7/12,I13,-F13)-F13)) -> 740.10267 | P13: =IF(F13="","",IF(C13<>"Closed",0,SUMIF('Referral Fees'!I11:BP11,"<="&Q13,'Referral Fees'!I13:BP13))) -> 0 | Q13: =IF(F13="","",IF(C13<>"Closed",0,IF(T13="",0,IF(T13<=0,0,IF(T13>I13,I13,T13))))) -> 0 | R13: =IF(C13<>"Closed","",IF(OR(E13="",I13=""),"",IF(Q13>=I13,"Paid off",EDATE(E13,Q13)))) | S13: =IF(OR(F13="",E13=""),"",(YEAR(C8)-YEAR(E13))*12+MONTH(C8)-MONTH(E13)) -> -2 | T13: =IF(S13="","",S13+IF(EDATE(E13,S13)<=C8,1,0)) -> -2 | U13: =IF(D13="","",DATE(YEAR(D13),MONTH(D13),1)) -> 46327 | V13: =IF(F13="","",M13+N13) -> 1160 | W13: =IF(C13="Closed",SUM(V13),0) -> 0 | X13: =IF(C13="Pipeline",SUM(V13),0) -> 1160 | Y13: =IF(C13="Pipeline",COUNTIF(C12:C13,"Pipeline"),"") -> 1
A14: 3 | B14: SAMPLE Client C (replace) | C14: Pipeline | D14: 46366 | E14: =IF(D14="","",EDATE(D14,1)) -> 46397 | F14: 17500 | G14: 0 | H14: 0.0899 | I14: 60 | J14: =IF(F14="","",F14*G14) -> 0 | K14: =IF(F14="","",F14-J14) -> 17500 | L14: =IF(OR(K14="",I14=""),"",PMT(H14/12,I14,-K14)) -> 363.18629 | M14: =IF(F14="","",IF(C14="Dead",0,F14*C5)) -> 175 | N14: =IF(F14="","",IF(C14="Dead",0,F14*C6)) -> 175 | O14: =IF(OR(F14="",I14=""),"",IF(C14="Dead",0,I14*PMT(C7/12,I14,-F14)-F14)) -> 223.30684 | P14: =IF(F14="","",IF(C14<>"Closed",0,SUMIF('Referral Fees'!I11:BP11,"<="&Q14,'Referral Fees'!I14:BP14))) -> 0 | Q14: =IF(F14="","",IF(C14<>"Closed",0,IF(T14="",0,IF(T14<=0,0,IF(T14>I14,I14,T14))))) -> 0 | R14: =IF(C14<>"Closed","",IF(OR(E14="",I14=""),"",IF(Q14>=I14,"Paid off",EDATE(E14,Q14)))) | S14: =IF(OR(F14="",E14=""),"",(YEAR(C8)-YEAR(E14))*12+MONTH(C8)-MONTH(E14)) -> -3 | T14: =IF(S14="","",S14+IF(EDATE(E14,S14)<=C8,1,0)) -> -3 | U14: =IF(D14="","",DATE(YEAR(D14),MONTH(D14),1)) -> 46357 | V14: =IF(F14="","",M14+N14) -> 350 | W14: =IF(C14="Closed",SUM(V14),0) -> 0 | X14: =IF(C14="Pipeline",SUM(V14),0) -> 350 | Y14: =IF(C14="Pipeline",COUNTIF(C12:C14,"Pipeline"),"") -> 2
E15: =IF(D15="","",EDATE(D15,1)) | J15: =IF(F15="","",F15*G15) | K15: =IF(F15="","",F15-J15) | L15: =IF(OR(K15="",I15=""),"",PMT(H15/12,I15,-K15)) | M15: =IF(F15="","",IF(C15="Dead",0,F15*C5)) | N15: =IF(F15="","",IF(C15="Dead",0,F15*C6)) | O15: =IF(OR(F15="",I15=""),"",IF(C15="Dead",0,I15*PMT(C7/12,I15,-F15)-F15)) | P15: =IF(F15="","",IF(C15<>"Closed",0,SUMIF('Referral Fees'!I11:BP11,"<="&Q15,'Referral Fees'!I15:BP15))) | Q15: =IF(F15="","",IF(C15<>"Closed",0,IF(T15="",0,IF(T15<=0,0,IF(T15>I15,I15,T15))))) | R15: =IF(C15<>"Closed","",IF(OR(E15="",I15=""),"",IF(Q15>=I15,"Paid off",EDATE(E15,Q15)))) | S15: =IF(OR(F15="",E15=""),"",(YEAR(C8)-YEAR(E15))*12+MONTH(C8)-MONTH(E15)) | T15: =IF(S15="","",S15+IF(EDATE(E15,S15)<=C8,1,0)) | U15: =IF(D15="","",DATE(YEAR(D15),MONTH(D15),1)) | V15: =IF(F15="","",M15+N15) | W15: =IF(C15="Closed",SUM(V15),0) -> 0 | X15: =IF(C15="Pipeline",SUM(V15),0) -> 0 | Y15: =IF(C15="Pipeline",COUNTIF(C12:C15,"Pipeline"),"")
E16: =IF(D16="","",EDATE(D16,1)) | J16: =IF(F16="","",F16*G16) | K16: =IF(F16="","",F16-J16) | L16: =IF(OR(K16="",I16=""),"",PMT(H16/12,I16,-K16)) | M16: =IF(F16="","",IF(C16="Dead",0,F16*C5)) | N16: =IF(F16="","",IF(C16="Dead",0,F16*C6)) | O16: =IF(OR(F16="",I16=""),"",IF(C16="Dead",0,I16*PMT(C7/12,I16,-F16)-F16)) | P16: =IF(F16="","",IF(C16<>"Closed",0,SUMIF('Referral Fees'!I11:BP11,"<="&Q16,'Referral Fees'!I16:BP16))) | Q16: =IF(F16="","",IF(C16<>"Closed",0,IF(T16="",0,IF(T16<=0,0,IF(T16>I16,I16,T16))))) | R16: =IF(C16<>"Closed","",IF(OR(E16="",I16=""),"",IF(Q16>=I16,"Paid off",EDATE(E16,Q16)))) | S16: =IF(OR(F16="",E16=""),"",(YEAR(C8)-YEAR(E16))*12+MONTH(C8)-MONTH(E16)) | T16: =IF(S16="","",S16+IF(EDATE(E16,S16)<=C8,1,0)) | U16: =IF(D16="","",DATE(YEAR(D16),MONTH(D16),1)) | V16: =IF(F16="","",M16+N16) | W16: =IF(C16="Closed",SUM(V16),0) -> 0 | X16: =IF(C16="Pipeline",SUM(V16),0) -> 0 | Y16: =IF(C16="Pipeline",COUNTIF(C12:C16,"Pipeline"),"")
E17: =IF(D17="","",EDATE(D17,1)) | J17: =IF(F17="","",F17*G17) | K17: =IF(F17="","",F17-J17) | L17: =IF(OR(K17="",I17=""),"",PMT(H17/12,I17,-K17)) | M17: =IF(F17="","",IF(C17="Dead",0,F17*C5)) | N17: =IF(F17="","",IF(C17="Dead",0,F17*C6)) | O17: =IF(OR(F17="",I17=""),"",IF(C17="Dead",0,I17*PMT(C7/12,I17,-F17)-F17)) | P17: =IF(F17="","",IF(C17<>"Closed",0,SUMIF('Referral Fees'!I11:BP11,"<="&Q17,'Referral Fees'!I17:BP17))) | Q17: =IF(F17="","",IF(C17<>"Closed",0,IF(T17="",0,IF(T17<=0,0,IF(T17>I17,I17,T17))))) | R17: =IF(C17<>"Closed","",IF(OR(E17="",I17=""),"",IF(Q17>=I17,"Paid off",EDATE(E17,Q17)))) | S17: =IF(OR(F17="",E17=""),"",(YEAR(C8)-YEAR(E17))*12+MONTH(C8)-MONTH(E17)) | T17: =IF(S17="","",S17+IF(EDATE(E17,S17)<=C8,1,0)) | U17: =IF(D17="","",DATE(YEAR(D17),MONTH(D17),1)) | V17: =IF(F17="","",M17+N17) | W17: =IF(C17="Closed",SUM(V17),0) -> 0 | X17: =IF(C17="Pipeline",SUM(V17),0) -> 0 | Y17: =IF(C17="Pipeline",COUNTIF(C12:C17,"Pipeline"),"")
E18: =IF(D18="","",EDATE(D18,1)) | J18: =IF(F18="","",F18*G18) | K18: =IF(F18="","",F18-J18) | L18: =IF(OR(K18="",I18=""),"",PMT(H18/12,I18,-K18)) | M18: =IF(F18="","",IF(C18="Dead",0,F18*C5)) | N18: =IF(F18="","",IF(C18="Dead",0,F18*C6)) | O18: =IF(OR(F18="",I18=""),"",IF(C18="Dead",0,I18*PMT(C7/12,I18,-F18)-F18)) | P18: =IF(F18="","",IF(C18<>"Closed",0,SUMIF('Referral Fees'!I11:BP11,"<="&Q18,'Referral Fees'!I18:BP18))) | Q18: =IF(F18="","",IF(C18<>"Closed",0,IF(T18="",0,IF(T18<=0,0,IF(T18>I18,I18,T18))))) | R18: =IF(C18<>"Closed","",IF(OR(E18="",I18=""),"",IF(Q18>=I18,"Paid off",EDATE(E18,Q18)))) | S18: =IF(OR(F18="",E18=""),"",(YEAR(C8)-YEAR(E18))*12+MONTH(C8)-MONTH(E18)) | T18: =IF(S18="","",S18+IF(EDATE(E18,S18)<=C8,1,0)) | U18: =IF(D18="","",DATE(YEAR(D18),MONTH(D18),1)) | V18: =IF(F18="","",M18+N18) | W18: =IF(C18="Closed",SUM(V18),0) -> 0 | X18: =IF(C18="Pipeline",SUM(V18),0) -> 0 | Y18: =IF(C18="Pipeline",COUNTIF(C12:C18,"Pipeline"),"")
E19: =IF(D19="","",EDATE(D19,1)) | J19: =IF(F19="","",F19*G19) | K19: =IF(F19="","",F19-J19) | L19: =IF(OR(K19="",I19=""),"",PMT(H19/12,I19,-K19)) | M19: =IF(F19="","",IF(C19="Dead",0,F19*C5)) | N19: =IF(F19="","",IF(C19="Dead",0,F19*C6)) | O19: =IF(OR(F19="",I19=""),"",IF(C19="Dead",0,I19*PMT(C7/12,I19,-F19)-F19)) | P19: =IF(F19="","",IF(C19<>"Closed",0,SUMIF('Referral Fees'!I11:BP11,"<="&Q19,'Referral Fees'!I19:BP19))) | Q19: =IF(F19="","",IF(C19<>"Closed",0,IF(T19="",0,IF(T19<=0,0,IF(T19>I19,I19,T19))))) | R19: =IF(C19<>"Closed","",IF(OR(E19="",I19=""),"",IF(Q19>=I19,"Paid off",EDATE(E19,Q19)))) | S19: =IF(OR(F19="",E19=""),"",(YEAR(C8)-YEAR(E19))*12+MONTH(C8)-MONTH(E19)) | T19: =IF(S19="","",S19+IF(EDATE(E19,S19)<=C8,1,0)) | U19: =IF(D19="","",DATE(YEAR(D19),MONTH(D19),1)) | V19: =IF(F19="","",M19+N19) | W19: =IF(C19="Closed",SUM(V19),0) -> 0 | X19: =IF(C19="Pipeline",SUM(V19),0) -> 0 | Y19: =IF(C19="Pipeline",COUNTIF(C12:C19,"Pipeline"),"")
E20: =IF(D20="","",EDATE(D20,1)) | J20: =IF(F20="","",F20*G20) | K20: =IF(F20="","",F20-J20) | L20: =IF(OR(K20="",I20=""),"",PMT(H20/12,I20,-K20)) | M20: =IF(F20="","",IF(C20="Dead",0,F20*C5)) | N20: =IF(F20="","",IF(C20="Dead",0,F20*C6)) | O20: =IF(OR(F20="",I20=""),"",IF(C20="Dead",0,I20*PMT(C7/12,I20,-F20)-F20)) | P20: =IF(F20="","",IF(C20<>"Closed",0,SUMIF('Referral Fees'!I11:BP11,"<="&Q20,'Referral Fees'!I20:BP20))) | Q20: =IF(F20="","",IF(C20<>"Closed",0,IF(T20="",0,IF(T20<=0,0,IF(T20>I20,I20,T20))))) | R20: =IF(C20<>"Closed","",IF(OR(E20="",I20=""),"",IF(Q20>=I20,"Paid off",EDATE(E20,Q20)))) | S20: =IF(OR(F20="",E20=""),"",(YEAR(C8)-YEAR(E20))*12+MONTH(C8)-MONTH(E20)) | T20: =IF(S20="","",S20+IF(EDATE(E20,S20)<=C8,1,0)) | U20: =IF(D20="","",DATE(YEAR(D20),MONTH(D20),1)) | V20: =IF(F20="","",M20+N20) | W20: =IF(C20="Closed",SUM(V20),0) -> 0 | X20: =IF(C20="Pipeline",SUM(V20),0) -> 0 | Y20: =IF(C20="Pipeline",COUNTIF(C12:C20,"Pipeline"),"")
E21: =IF(D21="","",EDATE(D21,1)) | J21: =IF(F21="","",F21*G21) | K21: =IF(F21="","",F21-J21) | L21: =IF(OR(K21="",I21=""),"",PMT(H21/12,I21,-K21)) | M21: =IF(F21="","",IF(C21="Dead",0,F21*C5)) | N21: =IF(F21="","",IF(C21="Dead",0,F21*C6)) | O21: =IF(OR(F21="",I21=""),"",IF(C21="Dead",0,I21*PMT(C7/12,I21,-F21)-F21)) | P21: =IF(F21="","",IF(C21<>"Closed",0,SUMIF('Referral Fees'!I11:BP11,"<="&Q21,'Referral Fees'!I21:BP21))) | Q21: =IF(F21="","",IF(C21<>"Closed",0,IF(T21="",0,IF(T21<=0,0,IF(T21>I21,I21,T21))))) | R21: =IF(C21<>"Closed","",IF(OR(E21="",I21=""),"",IF(Q21>=I21,"Paid off",EDATE(E21,Q21)))) | S21: =IF(OR(F21="",E21=""),"",(YEAR(C8)-YEAR(E21))*12+MONTH(C8)-MONTH(E21)) | T21: =IF(S21="","",S21+IF(EDATE(E21,S21)<=C8,1,0)) | U21: =IF(D21="","",DATE(YEAR(D21),MONTH(D21),1)) | V21: =IF(F21="","",M21+N21) | W21: =IF(C21="Closed",SUM(V21),0) -> 0 | X21: =IF(C21="Pipeline",SUM(V21),0) -> 0 | Y21: =IF(C21="Pipeline",COUNTIF(C12:C21,"Pipeline"),"")
E22: =IF(D22="","",EDATE(D22,1)) | J22: =IF(F22="","",F22*G22) | K22: =IF(F22="","",F22-J22) | L22: =IF(OR(K22="",I22=""),"",PMT(H22/12,I22,-K22)) | M22: =IF(F22="","",IF(C22="Dead",0,F22*C5)) | N22: =IF(F22="","",IF(C22="Dead",0,F22*C6)) | O22: =IF(OR(F22="",I22=""),"",IF(C22="Dead",0,I22*PMT(C7/12,I22,-F22)-F22)) | P22: =IF(F22="","",IF(C22<>"Closed",0,SUMIF('Referral Fees'!I11:BP11,"<="&Q22,'Referral Fees'!I22:BP22))) | Q22: =IF(F22="","",IF(C22<>"Closed",0,IF(T22="",0,IF(T22<=0,0,IF(T22>I22,I22,T22))))) | R22: =IF(C22<>"Closed","",IF(OR(E22="",I22=""),"",IF(Q22>=I22,"Paid off",EDATE(E22,Q22)))) | S22: =IF(OR(F22="",E22=""),"",(YEAR(C8)-YEAR(E22))*12+MONTH(C8)-MONTH(E22)) | T22: =IF(S22="","",S22+IF(EDATE(E22,S22)<=C8,1,0)) | U22: =IF(D22="","",DATE(YEAR(D22),MONTH(D22),1)) | V22: =IF(F22="","",M22+N22) | W22: =IF(C22="Closed",SUM(V22),0) -> 0 | X22: =IF(C22="Pipeline",SUM(V22),0) -> 0 | Y22: =IF(C22="Pipeline",COUNTIF(C12:C22,"Pipeline"),"")
E23: =IF(D23="","",EDATE(D23,1)) | J23: =IF(F23="","",F23*G23) | K23: =IF(F23="","",F23-J23) | L23: =IF(OR(K23="",I23=""),"",PMT(H23/12,I23,-K23)) | M23: =IF(F23="","",IF(C23="Dead",0,F23*C5)) | N23: =IF(F23="","",IF(C23="Dead",0,F23*C6)) | O23: =IF(OR(F23="",I23=""),"",IF(C23="Dead",0,I23*PMT(C7/12,I23,-F23)-F23)) | P23: =IF(F23="","",IF(C23<>"Closed",0,SUMIF('Referral Fees'!I11:BP11,"<="&Q23,'Referral Fees'!I23:BP23))) | Q23: =IF(F23="","",IF(C23<>"Closed",0,IF(T23="",0,IF(T23<=0,0,IF(T23>I23,I23,T23))))) | R23: =IF(C23<>"Closed","",IF(OR(E23="",I23=""),"",IF(Q23>=I23,"Paid off",EDATE(E23,Q23)))) | S23: =IF(OR(F23="",E23=""),"",(YEAR(C8)-YEAR(E23))*12+MONTH(C8)-MONTH(E23)) | T23: =IF(S23="","",S23+IF(EDATE(E23,S23)<=C8,1,0)) | U23: =IF(D23="","",DATE(YEAR(D23),MONTH(D23),1)) | V23: =IF(F23="","",M23+N23) | W23: =IF(C23="Closed",SUM(V23),0) -> 0 | X23: =IF(C23="Pipeline",SUM(V23),0) -> 0 | Y23: =IF(C23="Pipeline",COUNTIF(C12:C23,"Pipeline"),"")
E24: =IF(D24="","",EDATE(D24,1)) | J24: =IF(F24="","",F24*G24) | K24: =IF(F24="","",F24-J24) | L24: =IF(OR(K24="",I24=""),"",PMT(H24/12,I24,-K24)) | M24: =IF(F24="","",IF(C24="Dead",0,F24*C5)) | N24: =IF(F24="","",IF(C24="Dead",0,F24*C6)) | O24: =IF(OR(F24="",I24=""),"",IF(C24="Dead",0,I24*PMT(C7/12,I24,-F24)-F24)) | P24: =IF(F24="","",IF(C24<>"Closed",0,SUMIF('Referral Fees'!I11:BP11,"<="&Q24,'Referral Fees'!I24:BP24))) | Q24: =IF(F24="","",IF(C24<>"Closed",0,IF(T24="",0,IF(T24<=0,0,IF(T24>I24,I24,T24))))) | R24: =IF(C24<>"Closed","",IF(OR(E24="",I24=""),"",IF(Q24>=I24,"Paid off",EDATE(E24,Q24)))) | S24: =IF(OR(F24="",E24=""),"",(YEAR(C8)-YEAR(E24))*12+MONTH(C8)-MONTH(E24)) | T24: =IF(S24="","",S24+IF(EDATE(E24,S24)<=C8,1,0)) | U24: =IF(D24="","",DATE(YEAR(D24),MONTH(D24),1)) | V24: =IF(F24="","",M24+N24) | W24: =IF(C24="Closed",SUM(V24),0) -> 0 | X24: =IF(C24="Pipeline",SUM(V24),0) -> 0 | Y24: =IF(C24="Pipeline",COUNTIF(C12:C24,"Pipeline"),"")
E25: =IF(D25="","",EDATE(D25,1)) | J25: =IF(F25="","",F25*G25) | K25: =IF(F25="","",F25-J25) | L25: =IF(OR(K25="",I25=""),"",PMT(H25/12,I25,-K25)) | M25: =IF(F25="","",IF(C25="Dead",0,F25*C5)) | N25: =IF(F25="","",IF(C25="Dead",0,F25*C6)) | O25: =IF(OR(F25="",I25=""),"",IF(C25="Dead",0,I25*PMT(C7/12,I25,-F25)-F25)) | P25: =IF(F25="","",IF(C25<>"Closed",0,SUMIF('Referral Fees'!I11:BP11,"<="&Q25,'Referral Fees'!I25:BP25))) | Q25: =IF(F25="","",IF(C25<>"Closed",0,IF(T25="",0,IF(T25<=0,0,IF(T25>I25,I25,T25))))) | R25: =IF(C25<>"Closed","",IF(OR(E25="",I25=""),"",IF(Q25>=I25,"Paid off",EDATE(E25,Q25)))) | S25: =IF(OR(F25="",E25=""),"",(YEAR(C8)-YEAR(E25))*12+MONTH(C8)-MONTH(E25)) | T25: =IF(S25="","",S25+IF(EDATE(E25,S25)<=C8,1,0)) | U25: =IF(D25="","",DATE(YEAR(D25),MONTH(D25),1)) | V25: =IF(F25="","",M25+N25) | W25: =IF(C25="Closed",SUM(V25),0) -> 0 | X25: =IF(C25="Pipeline",SUM(V25),0) -> 0 | Y25: =IF(C25="Pipeline",COUNTIF(C12:C25,"Pipeline"),"")
E26: =IF(D26="","",EDATE(D26,1)) | J26: =IF(F26="","",F26*G26) | K26: =IF(F26="","",F26-J26) | L26: =IF(OR(K26="",I26=""),"",PMT(H26/12,I26,-K26)) | M26: =IF(F26="","",IF(C26="Dead",0,F26*C5)) | N26: =IF(F26="","",IF(C26="Dead",0,F26*C6)) | O26: =IF(OR(F26="",I26=""),"",IF(C26="Dead",0,I26*PMT(C7/12,I26,-F26)-F26)) | P26: =IF(F26="","",IF(C26<>"Closed",0,SUMIF('Referral Fees'!I11:BP11,"<="&Q26,'Referral Fees'!I26:BP26))) | Q26: =IF(F26="","",IF(C26<>"Closed",0,IF(T26="",0,IF(T26<=0,0,IF(T26>I26,I26,T26))))) | R26: =IF(C26<>"Closed","",IF(OR(E26="",I26=""),"",IF(Q26>=I26,"Paid off",EDATE(E26,Q26)))) | S26: =IF(OR(F26="",E26=""),"",(YEAR(C8)-YEAR(E26))*12+MONTH(C8)-MONTH(E26)) | T26: =IF(S26="","",S26+IF(EDATE(E26,S26)<=C8,1,0)) | U26: =IF(D26="","",DATE(YEAR(D26),MONTH(D26),1)) | V26: =IF(F26="","",M26+N26) | W26: =IF(C26="Closed",SUM(V26),0) -> 0 | X26: =IF(C26="Pipeline",SUM(V26),0) -> 0 | Y26: =IF(C26="Pipeline",COUNTIF(C12:C26,"Pipeline"),"")
E27: =IF(D27="","",EDATE(D27,1)) | J27: =IF(F27="","",F27*G27) | K27: =IF(F27="","",F27-J27) | L27: =IF(OR(K27="",I27=""),"",PMT(H27/12,I27,-K27)) | M27: =IF(F27="","",IF(C27="Dead",0,F27*C5)) | N27: =IF(F27="","",IF(C27="Dead",0,F27*C6)) | O27: =IF(OR(F27="",I27=""),"",IF(C27="Dead",0,I27*PMT(C7/12,I27,-F27)-F27)) | P27: =IF(F27="","",IF(C27<>"Closed",0,SUMIF('Referral Fees'!I11:BP11,"<="&Q27,'Referral Fees'!I27:BP27))) | Q27: =IF(F27="","",IF(C27<>"Closed",0,IF(T27="",0,IF(T27<=0,0,IF(T27>I27,I27,T27))))) | R27: =IF(C27<>"Closed","",IF(OR(E27="",I27=""),"",IF(Q27>=I27,"Paid off",EDATE(E27,Q27)))) | S27: =IF(OR(F27="",E27=""),"",(YEAR(C8)-YEAR(E27))*12+MONTH(C8)-MONTH(E27)) | T27: =IF(S27="","",S27+IF(EDATE(E27,S27)<=C8,1,0)) | U27: =IF(D27="","",DATE(YEAR(D27),MONTH(D27),1)) | V27: =IF(F27="","",M27+N27) | W27: =IF(C27="Closed",SUM(V27),0) -> 0 | X27: =IF(C27="Pipeline",SUM(V27),0) -> 0 | Y27: =IF(C27="Pipeline",COUNTIF(C12:C27,"Pipeline"),"")
E28: =IF(D28="","",EDATE(D28,1)) | J28: =IF(F28="","",F28*G28) | K28: =IF(F28="","",F28-J28) | L28: =IF(OR(K28="",I28=""),"",PMT(H28/12,I28,-K28)) | M28: =IF(F28="","",IF(C28="Dead",0,F28*C5)) | N28: =IF(F28="","",IF(C28="Dead",0,F28*C6)) | O28: =IF(OR(F28="",I28=""),"",IF(C28="Dead",0,I28*PMT(C7/12,I28,-F28)-F28)) | P28: =IF(F28="","",IF(C28<>"Closed",0,SUMIF('Referral Fees'!I11:BP11,"<="&Q28,'Referral Fees'!I28:BP28))) | Q28: =IF(F28="","",IF(C28<>"Closed",0,IF(T28="",0,IF(T28<=0,0,IF(T28>I28,I28,T28))))) | R28: =IF(C28<>"Closed","",IF(OR(E28="",I28=""),"",IF(Q28>=I28,"Paid off",EDATE(E28,Q28)))) | S28: =IF(OR(F28="",E28=""),"",(YEAR(C8)-YEAR(E28))*12+MONTH(C8)-MONTH(E28)) | T28: =IF(S28="","",S28+IF(EDATE(E28,S28)<=C8,1,0)) | U28: =IF(D28="","",DATE(YEAR(D28),MONTH(D28),1)) | V28: =IF(F28="","",M28+N28) | W28: =IF(C28="Closed",SUM(V28),0) -> 0 | X28: =IF(C28="Pipeline",SUM(V28),0) -> 0 | Y28: =IF(C28="Pipeline",COUNTIF(C12:C28,"Pipeline"),"")
E29: =IF(D29="","",EDATE(D29,1)) | J29: =IF(F29="","",F29*G29) | K29: =IF(F29="","",F29-J29) | L29: =IF(OR(K29="",I29=""),"",PMT(H29/12,I29,-K29)) | M29: =IF(F29="","",IF(C29="Dead",0,F29*C5)) | N29: =IF(F29="","",IF(C29="Dead",0,F29*C6)) | O29: =IF(OR(F29="",I29=""),"",IF(C29="Dead",0,I29*PMT(C7/12,I29,-F29)-F29)) | P29: =IF(F29="","",IF(C29<>"Closed",0,SUMIF('Referral Fees'!I11:BP11,"<="&Q29,'Referral Fees'!I29:BP29))) | Q29: =IF(F29="","",IF(C29<>"Closed",0,IF(T29="",0,IF(T29<=0,0,IF(T29>I29,I29,T29))))) | R29: =IF(C29<>"Closed","",IF(OR(E29="",I29=""),"",IF(Q29>=I29,"Paid off",EDATE(E29,Q29)))) | S29: =IF(OR(F29="",E29=""),"",(YEAR(C8)-YEAR(E29))*12+MONTH(C8)-MONTH(E29)) | T29: =IF(S29="","",S29+IF(EDATE(E29,S29)<=C8,1,0)) | U29: =IF(D29="","",DATE(YEAR(D29),MONTH(D29),1)) | V29: =IF(F29="","",M29+N29) | W29: =IF(C29="Closed",SUM(V29),0) -> 0 | X29: =IF(C29="Pipeline",SUM(V29),0) -> 0 | Y29: =IF(C29="Pipeline",COUNTIF(C12:C29,"Pipeline"),"")
E30: =IF(D30="","",EDATE(D30,1)) | J30: =IF(F30="","",F30*G30) | K30: =IF(F30="","",F30-J30) | L30: =IF(OR(K30="",I30=""),"",PMT(H30/12,I30,-K30)) | M30: =IF(F30="","",IF(C30="Dead",0,F30*C5)) | N30: =IF(F30="","",IF(C30="Dead",0,F30*C6)) | O30: =IF(OR(F30="",I30=""),"",IF(C30="Dead",0,I30*PMT(C7/12,I30,-F30)-F30)) | P30: =IF(F30="","",IF(C30<>"Closed",0,SUMIF('Referral Fees'!I11:BP11,"<="&Q30,'Referral Fees'!I30:BP30))) | Q30: =IF(F30="","",IF(C30<>"Closed",0,IF(T30="",0,IF(T30<=0,0,IF(T30>I30,I30,T30))))) | R30: =IF(C30<>"Closed","",IF(OR(E30="",I30=""),"",IF(Q30>=I30,"Paid off",EDATE(E30,Q30)))) | S30: =IF(OR(F30="",E30=""),"",(YEAR(C8)-YEAR(E30))*12+MONTH(C8)-MONTH(E30)) | T30: =IF(S30="","",S30+IF(EDATE(E30,S30)<=C8,1,0)) | U30: =IF(D30="","",DATE(YEAR(D30),MONTH(D30),1)) | V30: =IF(F30="","",M30+N30) | W30: =IF(C30="Closed",SUM(V30),0) -> 0 | X30: =IF(C30="Pipeline",SUM(V30),0) -> 0 | Y30: =IF(C30="Pipeline",COUNTIF(C12:C30,"Pipeline"),"")
E31: =IF(D31="","",EDATE(D31,1)) | J31: =IF(F31="","",F31*G31) | K31: =IF(F31="","",F31-J31) | L31: =IF(OR(K31="",I31=""),"",PMT(H31/12,I31,-K31)) | M31: =IF(F31="","",IF(C31="Dead",0,F31*C5)) | N31: =IF(F31="","",IF(C31="Dead",0,F31*C6)) | O31: =IF(OR(F31="",I31=""),"",IF(C31="Dead",0,I31*PMT(C7/12,I31,-F31)-F31)) | P31: =IF(F31="","",IF(C31<>"Closed",0,SUMIF('Referral Fees'!I11:BP11,"<="&Q31,'Referral Fees'!I31:BP31))) | Q31: =IF(F31="","",IF(C31<>"Closed",0,IF(T31="",0,IF(T31<=0,0,IF(T31>I31,I31,T31))))) | R31: =IF(C31<>"Closed","",IF(OR(E31="",I31=""),"",IF(Q31>=I31,"Paid off",EDATE(E31,Q31)))) | S31: =IF(OR(F31="",E31=""),"",(YEAR(C8)-YEAR(E31))*12+MONTH(C8)-MONTH(E31)) | T31: =IF(S31="","",S31+IF(EDATE(E31,S31)<=C8,1,0)) | U31: =IF(D31="","",DATE(YEAR(D31),MONTH(D31),1)) | V31: =IF(F31="","",M31+N31) | W31: =IF(C31="Closed",SUM(V31),0) -> 0 | X31: =IF(C31="Pipeline",SUM(V31),0) -> 0 | Y31: =IF(C31="Pipeline",COUNTIF(C12:C31,"Pipeline"),"")
E32: =IF(D32="","",EDATE(D32,1)) | J32: =IF(F32="","",F32*G32) | K32: =IF(F32="","",F32-J32) | L32: =IF(OR(K32="",I32=""),"",PMT(H32/12,I32,-K32)) | M32: =IF(F32="","",IF(C32="Dead",0,F32*C5)) | N32: =IF(F32="","",IF(C32="Dead",0,F32*C6)) | O32: =IF(OR(F32="",I32=""),"",IF(C32="Dead",0,I32*PMT(C7/12,I32,-F32)-F32)) | P32: =IF(F32="","",IF(C32<>"Closed",0,SUMIF('Referral Fees'!I11:BP11,"<="&Q32,'Referral Fees'!I32:BP32))) | Q32: =IF(F32="","",IF(C32<>"Closed",0,IF(T32="",0,IF(T32<=0,0,IF(T32>I32,I32,T32))))) | R32: =IF(C32<>"Closed","",IF(OR(E32="",I32=""),"",IF(Q32>=I32,"Paid off",EDATE(E32,Q32)))) | S32: =IF(OR(F32="",E32=""),"",(YEAR(C8)-YEAR(E32))*12+MONTH(C8)-MONTH(E32)) | T32: =IF(S32="","",S32+IF(EDATE(E32,S32)<=C8,1,0)) | U32: =IF(D32="","",DATE(YEAR(D32),MONTH(D32),1)) | V32: =IF(F32="","",M32+N32) | W32: =IF(C32="Closed",SUM(V32),0) -> 0 | X32: =IF(C32="Pipeline",SUM(V32),0) -> 0 | Y32: =IF(C32="Pipeline",COUNTIF(C12:C32,"Pipeline"),"")
E33: =IF(D33="","",EDATE(D33,1)) | J33: =IF(F33="","",F33*G33) | K33: =IF(F33="","",F33-J33) | L33: =IF(OR(K33="",I33=""),"",PMT(H33/12,I33,-K33)) | M33: =IF(F33="","",IF(C33="Dead",0,F33*C5)) | N33: =IF(F33="","",IF(C33="Dead",0,F33*C6)) | O33: =IF(OR(F33="",I33=""),"",IF(C33="Dead",0,I33*PMT(C7/12,I33,-F33)-F33)) | P33: =IF(F33="","",IF(C33<>"Closed",0,SUMIF('Referral Fees'!I11:BP11,"<="&Q33,'Referral Fees'!I33:BP33))) | Q33: =IF(F33="","",IF(C33<>"Closed",0,IF(T33="",0,IF(T33<=0,0,IF(T33>I33,I33,T33))))) | R33: =IF(C33<>"Closed","",IF(OR(E33="",I33=""),"",IF(Q33>=I33,"Paid off",EDATE(E33,Q33)))) | S33: =IF(OR(F33="",E33=""),"",(YEAR(C8)-YEAR(E33))*12+MONTH(C8)-MONTH(E33)) | T33: =IF(S33="","",S33+IF(EDATE(E33,S33)<=C8,1,0)) | U33: =IF(D33="","",DATE(YEAR(D33),MONTH(D33),1)) | V33: =IF(F33="","",M33+N33) | W33: =IF(C33="Closed",SUM(V33),0) -> 0 | X33: =IF(C33="Pipeline",SUM(V33),0) -> 0 | Y33: =IF(C33="Pipeline",COUNTIF(C12:C33,"Pipeline"),"")
E34: =IF(D34="","",EDATE(D34,1)) | J34: =IF(F34="","",F34*G34) | K34: =IF(F34="","",F34-J34) | L34: =IF(OR(K34="",I34=""),"",PMT(H34/12,I34,-K34)) | M34: =IF(F34="","",IF(C34="Dead",0,F34*C5)) | N34: =IF(F34="","",IF(C34="Dead",0,F34*C6)) | O34: =IF(OR(F34="",I34=""),"",IF(C34="Dead",0,I34*PMT(C7/12,I34,-F34)-F34)) | P34: =IF(F34="","",IF(C34<>"Closed",0,SUMIF('Referral Fees'!I11:BP11,"<="&Q34,'Referral Fees'!I34:BP34))) | Q34: =IF(F34="","",IF(C34<>"Closed",0,IF(T34="",0,IF(T34<=0,0,IF(T34>I34,I34,T34))))) | R34: =IF(C34<>"Closed","",IF(OR(E34="",I34=""),"",IF(Q34>=I34,"Paid off",EDATE(E34,Q34)))) | S34: =IF(OR(F34="",E34=""),"",(YEAR(C8)-YEAR(E34))*12+MONTH(C8)-MONTH(E34)) | T34: =IF(S34="","",S34+IF(EDATE(E34,S34)<=C8,1,0)) | U34: =IF(D34="","",DATE(YEAR(D34),MONTH(D34),1)) | V34: =IF(F34="","",M34+N34) | W34: =IF(C34="Closed",SUM(V34),0) -> 0 | X34: =IF(C34="Pipeline",SUM(V34),0) -> 0 | Y34: =IF(C34="Pipeline",COUNTIF(C12:C34,"Pipeline"),"")
E35: =IF(D35="","",EDATE(D35,1)) | J35: =IF(F35="","",F35*G35) | K35: =IF(F35="","",F35-J35) | L35: =IF(OR(K35="",I35=""),"",PMT(H35/12,I35,-K35)) | M35: =IF(F35="","",IF(C35="Dead",0,F35*C5)) | N35: =IF(F35="","",IF(C35="Dead",0,F35*C6)) | O35: =IF(OR(F35="",I35=""),"",IF(C35="Dead",0,I35*PMT(C7/12,I35,-F35)-F35)) | P35: =IF(F35="","",IF(C35<>"Closed",0,SUMIF('Referral Fees'!I11:BP11,"<="&Q35,'Referral Fees'!I35:BP35))) | Q35: =IF(F35="","",IF(C35<>"Closed",0,IF(T35="",0,IF(T35<=0,0,IF(T35>I35,I35,T35))))) | R35: =IF(C35<>"Closed","",IF(OR(E35="",I35=""),"",IF(Q35>=I35,"Paid off",EDATE(E35,Q35)))) | S35: =IF(OR(F35="",E35=""),"",(YEAR(C8)-YEAR(E35))*12+MONTH(C8)-MONTH(E35)) | T35: =IF(S35="","",S35+IF(EDATE(E35,S35)<=C8,1,0)) | U35: =IF(D35="","",DATE(YEAR(D35),MONTH(D35),1)) | V35: =IF(F35="","",M35+N35) | W35: =IF(C35="Closed",SUM(V35),0) -> 0 | X35: =IF(C35="Pipeline",SUM(V35),0) -> 0 | Y35: =IF(C35="Pipeline",COUNTIF(C12:C35,"Pipeline"),"")
E36: =IF(D36="","",EDATE(D36,1)) | J36: =IF(F36="","",F36*G36) | K36: =IF(F36="","",F36-J36) | L36: =IF(OR(K36="",I36=""),"",PMT(H36/12,I36,-K36)) | M36: =IF(F36="","",IF(C36="Dead",0,F36*C5)) | N36: =IF(F36="","",IF(C36="Dead",0,F36*C6)) | O36: =IF(OR(F36="",I36=""),"",IF(C36="Dead",0,I36*PMT(C7/12,I36,-F36)-F36)) | P36: =IF(F36="","",IF(C36<>"Closed",0,SUMIF('Referral Fees'!I11:BP11,"<="&Q36,'Referral Fees'!I36:BP36))) | Q36: =IF(F36="","",IF(C36<>"Closed",0,IF(T36="",0,IF(T36<=0,0,IF(T36>I36,I36,T36))))) | R36: =IF(C36<>"Closed","",IF(OR(E36="",I36=""),"",IF(Q36>=I36,"Paid off",EDATE(E36,Q36)))) | S36: =IF(OR(F36="",E36=""),"",(YEAR(C8)-YEAR(E36))*12+MONTH(C8)-MONTH(E36)) | T36: =IF(S36="","",S36+IF(EDATE(E36,S36)<=C8,1,0)) | U36: =IF(D36="","",DATE(YEAR(D36),MONTH(D36),1)) | V36: =IF(F36="","",M36+N36) | W36: =IF(C36="Closed",SUM(V36),0) -> 0 | X36: =IF(C36="Pipeline",SUM(V36),0) -> 0 | Y36: =IF(C36="Pipeline",COUNTIF(C12:C36,"Pipeline"),"")
E37: =IF(D37="","",EDATE(D37,1)) | J37: =IF(F37="","",F37*G37) | K37: =IF(F37="","",F37-J37) | L37: =IF(OR(K37="",I37=""),"",PMT(H37/12,I37,-K37)) | M37: =IF(F37="","",IF(C37="Dead",0,F37*C5)) | N37: =IF(F37="","",IF(C37="Dead",0,F37*C6)) | O37: =IF(OR(F37="",I37=""),"",IF(C37="Dead",0,I37*PMT(C7/12,I37,-F37)-F37)) | P37: =IF(F37="","",IF(C37<>"Closed",0,SUMIF('Referral Fees'!I11:BP11,"<="&Q37,'Referral Fees'!I37:BP37))) | Q37: =IF(F37="","",IF(C37<>"Closed",0,IF(T37="",0,IF(T37<=0,0,IF(T37>I37,I37,T37))))) | R37: =IF(C37<>"Closed","",IF(OR(E37="",I37=""),"",IF(Q37>=I37,"Paid off",EDATE(E37,Q37)))) | S37: =IF(OR(F37="",E37=""),"",(YEAR(C8)-YEAR(E37))*12+MONTH(C8)-MONTH(E37)) | T37: =IF(S37="","",S37+IF(EDATE(E37,S37)<=C8,1,0)) | U37: =IF(D37="","",DATE(YEAR(D37),MONTH(D37),1)) | V37: =IF(F37="","",M37+N37) | W37: =IF(C37="Closed",SUM(V37),0) -> 0 | X37: =IF(C37="Pipeline",SUM(V37),0) -> 0 | Y37: =IF(C37="Pipeline",COUNTIF(C12:C37,"Pipeline"),"")
E38: =IF(D38="","",EDATE(D38,1)) | J38: =IF(F38="","",F38*G38) | K38: =IF(F38="","",F38-J38) | L38: =IF(OR(K38="",I38=""),"",PMT(H38/12,I38,-K38)) | M38: =IF(F38="","",IF(C38="Dead",0,F38*C5)) | N38: =IF(F38="","",IF(C38="Dead",0,F38*C6)) | O38: =IF(OR(F38="",I38=""),"",IF(C38="Dead",0,I38*PMT(C7/12,I38,-F38)-F38)) | P38: =IF(F38="","",IF(C38<>"Closed",0,SUMIF('Referral Fees'!I11:BP11,"<="&Q38,'Referral Fees'!I38:BP38))) | Q38: =IF(F38="","",IF(C38<>"Closed",0,IF(T38="",0,IF(T38<=0,0,IF(T38>I38,I38,T38))))) | R38: =IF(C38<>"Closed","",IF(OR(E38="",I38=""),"",IF(Q38>=I38,"Paid off",EDATE(E38,Q38)))) | S38: =IF(OR(F38="",E38=""),"",(YEAR(C8)-YEAR(E38))*12+MONTH(C8)-MONTH(E38)) | T38: =IF(S38="","",S38+IF(EDATE(E38,S38)<=C8,1,0)) | U38: =IF(D38="","",DATE(YEAR(D38),MONTH(D38),1)) | V38: =IF(F38="","",M38+N38) | W38: =IF(C38="Closed",SUM(V38),0) -> 0 | X38: =IF(C38="Pipeline",SUM(V38),0) -> 0 | Y38: =IF(C38="Pipeline",COUNTIF(C12:C38,"Pipeline"),"")
E39: =IF(D39="","",EDATE(D39,1)) | J39: =IF(F39="","",F39*G39) | K39: =IF(F39="","",F39-J39) | L39: =IF(OR(K39="",I39=""),"",PMT(H39/12,I39,-K39)) | M39: =IF(F39="","",IF(C39="Dead",0,F39*C5)) | N39: =IF(F39="","",IF(C39="Dead",0,F39*C6)) | O39: =IF(OR(F39="",I39=""),"",IF(C39="Dead",0,I39*PMT(C7/12,I39,-F39)-F39)) | P39: =IF(F39="","",IF(C39<>"Closed",0,SUMIF('Referral Fees'!I11:BP11,"<="&Q39,'Referral Fees'!I39:BP39))) | Q39: =IF(F39="","",IF(C39<>"Closed",0,IF(T39="",0,IF(T39<=0,0,IF(T39>I39,I39,T39))))) | R39: =IF(C39<>"Closed","",IF(OR(E39="",I39=""),"",IF(Q39>=I39,"Paid off",EDATE(E39,Q39)))) | S39: =IF(OR(F39="",E39=""),"",(YEAR(C8)-YEAR(E39))*12+MONTH(C8)-MONTH(E39)) | T39: =IF(S39="","",S39+IF(EDATE(E39,S39)<=C8,1,0)) | U39: =IF(D39="","",DATE(YEAR(D39),MONTH(D39),1)) | V39: =IF(F39="","",M39+N39) | W39: =IF(C39="Closed",SUM(V39),0) -> 0 | X39: =IF(C39="Pipeline",SUM(V39),0) -> 0 | Y39: =IF(C39="Pipeline",COUNTIF(C12:C39,"Pipeline"),"")
E40: =IF(D40="","",EDATE(D40,1)) | J40: =IF(F40="","",F40*G40) | K40: =IF(F40="","",F40-J40) | L40: =IF(OR(K40="",I40=""),"",PMT(H40/12,I40,-K40)) | M40: =IF(F40="","",IF(C40="Dead",0,F40*C5)) | N40: =IF(F40="","",IF(C40="Dead",0,F40*C6)) | O40: =IF(OR(F40="",I40=""),"",IF(C40="Dead",0,I40*PMT(C7/12,I40,-F40)-F40)) | P40: =IF(F40="","",IF(C40<>"Closed",0,SUMIF('Referral Fees'!I11:BP11,"<="&Q40,'Referral Fees'!I40:BP40))) | Q40: =IF(F40="","",IF(C40<>"Closed",0,IF(T40="",0,IF(T40<=0,0,IF(T40>I40,I40,T40))))) | R40: =IF(C40<>"Closed","",IF(OR(E40="",I40=""),"",IF(Q40>=I40,"Paid off",EDATE(E40,Q40)))) | S40: =IF(OR(F40="",E40=""),"",(YEAR(C8)-YEAR(E40))*12+MONTH(C8)-MONTH(E40)) | T40: =IF(S40="","",S40+IF(EDATE(E40,S40)<=C8,1,0)) | U40: =IF(D40="","",DATE(YEAR(D40),MONTH(D40),1)) | V40: =IF(F40="","",M40+N40) | W40: =IF(C40="Closed",SUM(V40),0) -> 0 | X40: =IF(C40="Pipeline",SUM(V40),0) -> 0 | Y40: =IF(C40="Pipeline",COUNTIF(C12:C40,"Pipeline"),"")
E41: =IF(D41="","",EDATE(D41,1)) | J41: =IF(F41="","",F41*G41) | K41: =IF(F41="","",F41-J41) | L41: =IF(OR(K41="",I41=""),"",PMT(H41/12,I41,-K41)) | M41: =IF(F41="","",IF(C41="Dead",0,F41*C5)) | N41: =IF(F41="","",IF(C41="Dead",0,F41*C6)) | O41: =IF(OR(F41="",I41=""),"",IF(C41="Dead",0,I41*PMT(C7/12,I41,-F41)-F41)) | P41: =IF(F41="","",IF(C41<>"Closed",0,SUMIF('Referral Fees'!I11:BP11,"<="&Q41,'Referral Fees'!I41:BP41))) | Q41: =IF(F41="","",IF(C41<>"Closed",0,IF(T41="",0,IF(T41<=0,0,IF(T41>I41,I41,T41))))) | R41: =IF(C41<>"Closed","",IF(OR(E41="",I41=""),"",IF(Q41>=I41,"Paid off",EDATE(E41,Q41)))) | S41: =IF(OR(F41="",E41=""),"",(YEAR(C8)-YEAR(E41))*12+MONTH(C8)-MONTH(E41)) | T41: =IF(S41="","",S41+IF(EDATE(E41,S41)<=C8,1,0)) | U41: =IF(D41="","",DATE(YEAR(D41),MONTH(D41),1)) | V41: =IF(F41="","",M41+N41) | W41: =IF(C41="Closed",SUM(V41),0) -> 0 | X41: =IF(C41="Pipeline",SUM(V41),0) -> 0 | Y41: =IF(C41="Pipeline",COUNTIF(C12:C41,"Pipeline"),"")
...

Sheet Loan Detail
A1: Loan Detail | Tabla de Amortizacion
A2: Pick a Loan # in the blue cell B3. Everything else on this tab is calculated.
A3: Loan # | B3: 1 | D3: Costo de Equipo | E3: =IF(B8="","",INDEX(Loans!F12:F61,B8)) -> 38127.43 | F3: Fee Table (base = Costo de Equipo)
A4: Client or Company | B4: =IF(B8="","",INDEX(Loans!B12:B61,B8)) -> SAMPLE Client A (replace) | D4: Pronto % | E4: =IF(B8="","",INDEX(Loans!G12:G61,B8)) -> 0 | F4: Origination Fee | H4: =IF(B8="","",INDEX(Loans!M12:M61,B8)) -> 381.2743
A5: Status | B5: =IF(B8="","",INDEX(Loans!C12:C61,B8)) -> Closed | D5: Pronto $ | E5: =IF(B8="","",INDEX(Loans!J12:J61,B8)) -> 0 | F5: Legal/Closing Fee | H5: =IF(B8="","",INDEX(Loans!N12:N61,B8)) -> 381.2743
A6: Closing Date | B6: =IF(B8="","",INDEX(Loans!D12:D61,B8)) -> 46218 | D6: Monto a Financiar | E6: =IF(B8="","",INDEX(Loans!K12:K61,B8)) -> 38127.43 | F6: Referral Fee, lifetime | H6: =SUM(G13:G72) -> 486.52091
A7: First Payment Date | B7: =IF(B8="","",INDEX(Loans!E12:E61,B8)) -> 46249 | D7: Interes | E7: =IF(B8="","",INDEX(Loans!H12:H61,B8)) -> 0.0899 | F7: Referral Fee, first 12 months | H7: =SUM(G13:G24) -> 173.35197
A8: Row in Loans (helper) | B8: =IF(COUNTIF(Loans!A12:A61,B3)=0,"",MATCH(B3,Loans!A12:A61,0)) -> 1 | D8: Termino (mo.) | E8: =IF(B8="","",INDEX(Loans!I12:I61,B8)) -> 60 | F8: Total Fees (lifetime) | H8: =SUM(H4:H6) -> 1249.0695
D9: Pago Mensual | E9: =IF(B8="","",INDEX(Loans!L12:L61,B8)) -> 791.2777 | F9: Referral loan payment (helper) | H9: =IF(B8="","",PMT(Loans!C7/12,E8,-E3)) -> 643.56585
A10: Referral Fee shows what the fee would be if the loan were Closed. Billing tabs only use Closed loans. | F10: Check: lifetime referral vs Loans tab | H10: =IF(B8="","",IF(B5="Dead","n/a (Dead)",IF(ABS(H6-INDEX(Loans!O12:O61,B8))<0.005,"OK","CHECK"))) -> OK
A12: Pmt # | B12: Pmt Date | C12: Principal | D12: Interest | E12: P&I Pmt | F12: Balance | G12: Referral Fee | H12: Ref. loan principal (helper) | I12: Ref. loan balance (helper)
A13: =IF(B8="","",IF(E6="","",IF(E8<1,"",1))) -> 1 | B13: =IF(OR(A13="",B7=""),"",EDATE(B7,A13-1)) -> 46249 | C13: =IF(A13="","",E13-D13) -> 505.63971 | D13: =IF(A13="","",E6*E7/12) -> 285.638 | E13: =IF(A13="","",E9) -> 791.2777 | F13: =IF(A13="","",IF(A13=E8,0,E6-C13)) -> 37621.79 | G13: =IF(A13="","",E3*Loans!C7/12) -> 15.886429 | H13: =IF(A13="","",H9-G13) -> 627.67942 | I13: =IF(A13="","",IF(A13=E8,0,E3-H13)) -> 37499.751
A14: =IF(A13="","",IF(A13<E8,A13+1,"")) -> 2 | B14: =IF(OR(A14="",B7=""),"",EDATE(B7,A14-1)) -> 46280 | C14: =IF(A14="","",E14-D14) -> 509.42779 | D14: =IF(A14="","",F13*E7/12) -> 281.84991 | E14: =IF(A14="","",E9) -> 791.2777 | F14: =IF(A14="","",IF(A14=E8,0,F13-C14)) -> 37112.363 | G14: =IF(A14="","",I13*Loans!C7/12) -> 15.624896 | H14: =IF(A14="","",H9-G14) -> 627.94095 | I14: =IF(A14="","",IF(A14=E8,0,I13-H14)) -> 36871.81
A15: =IF(A14="","",IF(A14<E8,A14+1,"")) -> 3 | B15: =IF(OR(A15="",B7=""),"",EDATE(B7,A15-1)) -> 46310 | C15: =IF(A15="","",E15-D15) -> 513.24426 | D15: =IF(A15="","",F14*E7/12) -> 278.03345 | E15: =IF(A15="","",E9) -> 791.2777 | F15: =IF(A15="","",IF(A15=E8,0,F14-C15)) -> 36599.118 | G15: =IF(A15="","",I14*Loans!C7/12) -> 15.363254 | H15: =IF(A15="","",H9-G15) -> 628.20259 | I15: =IF(A15="","",IF(A15=E8,0,I14-H15)) -> 36243.607
A16: =IF(A15="","",IF(A15<E8,A15+1,"")) -> 4 | B16: =IF(OR(A16="",B7=""),"",EDATE(B7,A16-1)) -> 46341 | C16: =IF(A16="","",E16-D16) -> 517.08931 | D16: =IF(A16="","",F15*E7/12) -> 274.18839 | E16: =IF(A16="","",E9) -> 791.2777 | F16: =IF(A16="","",IF(A16=E8,0,F15-C16)) -> 36082.029 | G16: =IF(A16="","",I15*Loans!C7/12) -> 15.101503 | H16: =IF(A16="","",H9-G16) -> 628.46435 | I16: =IF(A16="","",IF(A16=E8,0,I15-H16)) -> 35615.143
A17: =IF(A16="","",IF(A16<E8,A16+1,"")) -> 5 | B17: =IF(OR(A17="",B7=""),"",EDATE(B7,A17-1)) -> 46371 | C17: =IF(A17="","",E17-D17) -> 520.96317 | D17: =IF(A17="","",F16*E7/12) -> 270.31453 | E17: =IF(A17="","",E9) -> 791.2777 | F17: =IF(A17="","",IF(A17=E8,0,F16-C17)) -> 35561.066 | G17: =IF(A17="","",I16*Loans!C7/12) -> 14.839643 | H17: =IF(A17="","",H9-G17) -> 628.72621 | I17: =IF(A17="","",IF(A17=E8,0,I16-H17)) -> 34986.416
A18: =IF(A17="","",IF(A17<E8,A17+1,"")) -> 6 | B18: =IF(OR(A18="",B7=""),"",EDATE(B7,A18-1)) -> 46402 | C18: =IF(A18="","",E18-D18) -> 524.86605 | D18: =IF(A18="","",F17*E7/12) -> 266.41165 | E18: =IF(A18="","",E9) -> 791.2777 | F18: =IF(A18="","",IF(A18=E8,0,F17-C18)) -> 35036.2 | G18: =IF(A18="","",I17*Loans!C7/12) -> 14.577674 | H18: =IF(A18="","",H9-G18) -> 628.98817 | I18: =IF(A18="","",IF(A18=E8,0,I17-H18)) -> 34357.428
A19: =IF(A18="","",IF(A18<E8,A18+1,"")) -> 7 | B19: =IF(OR(A19="",B7=""),"",EDATE(B7,A19-1)) -> 46433 | C19: =IF(A19="","",E19-D19) -> 528.79817 | D19: =IF(A19="","",F18*E7/12) -> 262.47953 | E19: =IF(A19="","",E9) -> 791.2777 | F19: =IF(A19="","",IF(A19=E8,0,F18-C19)) -> 34507.402 | G19: =IF(A19="","",I18*Loans!C7/12) -> 14.315595 | H19: =IF(A19="","",H9-G19) -> 629.25025 | I19: =IF(A19="","",IF(A19=E8,0,I18-H19)) -> 33728.178
A20: =IF(A19="","",IF(A19<E8,A19+1,"")) -> 8 | B20: =IF(OR(A20="",B7=""),"",EDATE(B7,A20-1)) -> 46461 | C20: =IF(A20="","",E20-D20) -> 532.75975 | D20: =IF(A20="","",F19*E7/12) -> 258.51795 | E20: =IF(A20="","",E9) -> 791.2777 | F20: =IF(A20="","",IF(A20=E8,0,F19-C20)) -> 33974.642 | G20: =IF(A20="","",I19*Loans!C7/12) -> 14.053408 | H20: =IF(A20="","",H9-G20) -> 629.51244 | I20: =IF(A20="","",IF(A20=E8,0,I19-H20)) -> 33098.666
A21: =IF(A20="","",IF(A20<E8,A20+1,"")) -> 9 | B21: =IF(OR(A21="",B7=""),"",EDATE(B7,A21-1)) -> 46492 | C21: =IF(A21="","",E21-D21) -> 536.75101 | D21: =IF(A21="","",F20*E7/12) -> 254.52669 | E21: =IF(A21="","",E9) -> 791.2777 | F21: =IF(A21="","",IF(A21=E8,0,F20-C21)) -> 33437.891 | G21: =IF(A21="","",I20*Loans!C7/12) -> 13.791111 | H21: =IF(A21="","",H9-G21) -> 629.77474 | I21: =IF(A21="","",IF(A21=E8,0,I20-H21)) -> 32468.891
A22: =IF(A21="","",IF(A21<E8,A21+1,"")) -> 10 | B22: =IF(OR(A22="",B7=""),"",EDATE(B7,A22-1)) -> 46522 | C22: =IF(A22="","",E22-D22) -> 540.77217 | D22: =IF(A22="","",F21*E7/12) -> 250.50553 | E22: =IF(A22="","",E9) -> 791.2777 | F22: =IF(A22="","",IF(A22=E8,0,F21-C22)) -> 32897.119 | G22: =IF(A22="","",I21*Loans!C7/12) -> 13.528705 | H22: =IF(A22="","",H9-G22) -> 630.03714 | I22: =IF(A22="","",IF(A22=E8,0,I21-H22)) -> 31838.854
A23: =IF(A22="","",IF(A22<E8,A22+1,"")) -> 11 | B23: =IF(OR(A23="",B7=""),"",EDATE(B7,A23-1)) -> 46553 | C23: =IF(A23="","",E23-D23) -> 544.82346 | D23: =IF(A23="","",F22*E7/12) -> 246.45425 | E23: =IF(A23="","",E9) -> 791.2777 | F23: =IF(A23="","",IF(A23=E8,0,F22-C23)) -> 32352.295 | G23: =IF(A23="","",I22*Loans!C7/12) -> 13.266189 | H23: =IF(A23="","",H9-G23) -> 630.29966 | I23: =IF(A23="","",IF(A23=E8,0,I22-H23)) -> 31208.554
A24: =IF(A23="","",IF(A23<E8,A23+1,"")) -> 12 | B24: =IF(OR(A24="",B7=""),"",EDATE(B7,A24-1)) -> 46583 | C24: =IF(A24="","",E24-D24) -> 548.90509 | D24: =IF(A24="","",F23*E7/12) -> 242.37261 | E24: =IF(A24="","",E9) -> 791.2777 | F24: =IF(A24="","",IF(A24=E8,0,F23-C24)) -> 31803.39 | G24: =IF(A24="","",I23*Loans!C7/12) -> 13.003564 | H24: =IF(A24="","",H9-G24) -> 630.56228 | I24: =IF(A24="","",IF(A24=E8,0,I23-H24)) -> 30577.992
A25: =IF(A24="","",IF(A24<E8,A24+1,"")) -> 13 | B25: =IF(OR(A25="",B7=""),"",EDATE(B7,A25-1)) -> 46614 | C25: =IF(A25="","",E25-D25) -> 553.01731 | D25: =IF(A25="","",F24*E7/12) -> 238.2604 | E25: =IF(A25="","",E9) -> 791.2777 | F25: =IF(A25="","",IF(A25=E8,0,F24-C25)) -> 31250.373 | G25: =IF(A25="","",I24*Loans!C7/12) -> 12.74083 | H25: =IF(A25="","",H9-G25) -> 630.82502 | I25: =IF(A25="","",IF(A25=E8,0,I24-H25)) -> 29947.167
A26: =IF(A25="","",IF(A25<E8,A25+1,"")) -> 14 | B26: =IF(OR(A26="",B7=""),"",EDATE(B7,A26-1)) -> 46645 | C26: =IF(A26="","",E26-D26) -> 557.16033 | D26: =IF(A26="","",F25*E7/12) -> 234.11738 | E26: =IF(A26="","",E9) -> 791.2777 | F26: =IF(A26="","",IF(A26=E8,0,F25-C26)) -> 30693.212 | G26: =IF(A26="","",I25*Loans!C7/12) -> 12.477986 | H26: =IF(A26="","",H9-G26) -> 631.08786 | I26: =IF(A26="","",IF(A26=E8,0,I25-H26)) -> 29316.079
A27: =IF(A26="","",IF(A26<E8,A26+1,"")) -> 15 | B27: =IF(OR(A27="",B7=""),"",EDATE(B7,A27-1)) -> 46675 | C27: =IF(A27="","",E27-D27) -> 561.33439 | D27: =IF(A27="","",F26*E7/12) -> 229.94332 | E27: =IF(A27="","",E9) -> 791.2777 | F27: =IF(A27="","",IF(A27=E8,0,F26-C27)) -> 30131.878 | G27: =IF(A27="","",I26*Loans!C7/12) -> 12.215033 | H27: =IF(A27="","",H9-G27) -> 631.35082 | I27: =IF(A27="","",IF(A27=E8,0,I26-H27)) -> 28684.728
A28: =IF(A27="","",IF(A27<E8,A27+1,"")) -> 16 | B28: =IF(OR(A28="",B7=""),"",EDATE(B7,A28-1)) -> 46706 | C28: =IF(A28="","",E28-D28) -> 565.53972 | D28: =IF(A28="","",F27*E7/12) -> 225.73799 | E28: =IF(A28="","",E9) -> 791.2777 | F28: =IF(A28="","",IF(A28=E8,0,F27-C28)) -> 29566.338 | G28: =IF(A28="","",I27*Loans!C7/12) -> 11.95197 | H28: =IF(A28="","",H9-G28) -> 631.61388 | I28: =IF(A28="","",IF(A28=E8,0,I27-H28)) -> 28053.114
A29: =IF(A28="","",IF(A28<E8,A28+1,"")) -> 17 | B29: =IF(OR(A29="",B7=""),"",EDATE(B7,A29-1)) -> 46736 | C29: =IF(A29="","",E29-D29) -> 569.77655 | D29: =IF(A29="","",F28*E7/12) -> 221.50115 | E29: =IF(A29="","",E9) -> 791.2777 | F29: =IF(A29="","",IF(A29=E8,0,F28-C29)) -> 28996.562 | G29: =IF(A29="","",I28*Loans!C7/12) -> 11.688798 | H29: =IF(A29="","",H9-G29) -> 631.87705 | I29: =IF(A29="","",IF(A29=E8,0,I28-H29)) -> 27421.237
A30: =IF(A29="","",IF(A29<E8,A29+1,"")) -> 18 | B30: =IF(OR(A30="",B7=""),"",EDATE(B7,A30-1)) -> 46767 | C30: =IF(A30="","",E30-D30) -> 574.04513 | D30: =IF(A30="","",F29*E7/12) -> 217.23258 | E30: =IF(A30="","",E9) -> 791.2777 | F30: =IF(A30="","",IF(A30=E8,0,F29-C30)) -> 28422.517 | G30: =IF(A30="","",I29*Loans!C7/12) -> 11.425515 | H30: =IF(A30="","",H9-G30) -> 632.14033 | I30: =IF(A30="","",IF(A30=E8,0,I29-H30)) -> 26789.097
A31: =IF(A30="","",IF(A30<E8,A30+1,"")) -> 19 | B31: =IF(OR(A31="",B7=""),"",EDATE(B7,A31-1)) -> 46798 | C31: =IF(A31="","",E31-D31) -> 578.34568 | D31: =IF(A31="","",F30*E7/12) -> 212.93202 | E31: =IF(A31="","",E9) -> 791.2777 | F31: =IF(A31="","",IF(A31=E8,0,F30-C31)) -> 27844.171 | G31: =IF(A31="","",I30*Loans!C7/12) -> 11.162124 | H31: =IF(A31="","",H9-G31) -> 632.40372 | I31: =IF(A31="","",IF(A31=E8,0,I30-H31)) -> 26156.693
A32: =IF(A31="","",IF(A31<E8,A31+1,"")) -> 20 | B32: =IF(OR(A32="",B7=""),"",EDATE(B7,A32-1)) -> 46827 | C32: =IF(A32="","",E32-D32) -> 582.67846 | D32: =IF(A32="","",F31*E7/12) -> 208.59925 | E32: =IF(A32="","",E9) -> 791.2777 | F32: =IF(A32="","",IF(A32=E8,0,F31-C32)) -> 27261.492 | G32: =IF(A32="","",I31*Loans!C7/12) -> 10.898622 | H32: =IF(A32="","",H9-G32) -> 632.66723 | I32: =IF(A32="","",IF(A32=E8,0,I31-H32)) -> 25524.026
A33: =IF(A32="","",IF(A32<E8,A32+1,"")) -> 21 | B33: =IF(OR(A33="",B7=""),"",EDATE(B7,A33-1)) -> 46858 | C33: =IF(A33="","",E33-D33) -> 587.04369 | D33: =IF(A33="","",F32*E7/12) -> 204.23401 | E33: =IF(A33="","",E9) -> 791.2777 | F33: =IF(A33="","",IF(A33=E8,0,F32-C33)) -> 26674.449 | G33: =IF(A33="","",I32*Loans!C7/12) -> 10.635011 | H33: =IF(A33="","",H9-G33) -> 632.93084 | I33: =IF(A33="","",IF(A33=E8,0,I32-H33)) -> 24891.095
A34: =IF(A33="","",IF(A33<E8,A33+1,"")) -> 22 | B34: =IF(OR(A34="",B7=""),"",EDATE(B7,A34-1)) -> 46888 | C34: =IF(A34="","",E34-D34) -> 591.44163 | D34: =IF(A34="","",F33*E7/12) -> 199.83608 | E34: =IF(A34="","",E9) -> 791.2777 | F34: =IF(A34="","",IF(A34=E8,0,F33-C34)) -> 26083.007 | G34: =IF(A34="","",I33*Loans!C7/12) -> 10.37129 | H34: =IF(A34="","",H9-G34) -> 633.19456 | I34: =IF(A34="","",IF(A34=E8,0,I33-H34)) -> 24257.9
A35: =IF(A34="","",IF(A34<E8,A34+1,"")) -> 23 | B35: =IF(OR(A35="",B7=""),"",EDATE(B7,A35-1)) -> 46919 | C35: =IF(A35="","",E35-D35) -> 595.87251 | D35: =IF(A35="","",F34*E7/12) -> 195.4052 | E35: =IF(A35="","",E9) -> 791.2777 | F35: =IF(A35="","",IF(A35=E8,0,F34-C35)) -> 25487.135 | G35: =IF(A35="","",I34*Loans!C7/12) -> 10.107459 | H35: =IF(A35="","",H9-G35) -> 633.45839 | I35: =IF(A35="","",IF(A35=E8,0,I34-H35)) -> 23624.442
A36: =IF(A35="","",IF(A35<E8,A35+1,"")) -> 24 | B36: =IF(OR(A36="",B7=""),"",EDATE(B7,A36-1)) -> 46949 | C36: =IF(A36="","",E36-D36) -> 600.33659 | D36: =IF(A36="","",F35*E7/12) -> 190.94112 | E36: =IF(A36="","",E9) -> 791.2777 | F36: =IF(A36="","",IF(A36=E8,0,F35-C36)) -> 24886.798 | G36: =IF(A36="","",I35*Loans!C7/12) -> 9.8435175 | H36: =IF(A36="","",H9-G36) -> 633.72233 | I36: =IF(A36="","",IF(A36=E8,0,I35-H36)) -> 22990.72
A37: =IF(A36="","",IF(A36<E8,A36+1,"")) -> 25 | B37: =IF(OR(A37="",B7=""),"",EDATE(B7,A37-1)) -> 46980 | C37: =IF(A37="","",E37-D37) -> 604.83411 | D37: =IF(A37="","",F36*E7/12) -> 186.4436 | E37: =IF(A37="","",E9) -> 791.2777 | F37: =IF(A37="","",IF(A37=E8,0,F36-C37)) -> 24281.964 | G37: =IF(A37="","",I36*Loans!C7/12) -> 9.5794666 | H37: =IF(A37="","",H9-G37) -> 633.98638 | I37: =IF(A37="","",IF(A37=E8,0,I36-H37)) -> 22356.733
A38: =IF(A37="","",IF(A37<E8,A37+1,"")) -> 26 | B38: =IF(OR(A38="",B7=""),"",EDATE(B7,A38-1)) -> 47011 | C38: =IF(A38="","",E38-D38) -> 609.36532 | D38: =IF(A38="","",F37*E7/12) -> 181.91238 | E38: =IF(A38="","",E9) -> 791.2777 | F38: =IF(A38="","",IF(A38=E8,0,F37-C38)) -> 23672.599 | G38: =IF(A38="","",I37*Loans!C7/12) -> 9.3153056 | H38: =IF(A38="","",H9-G38) -> 634.25054 | I38: =IF(A38="","",IF(A38=E8,0,I37-H38)) -> 21722.483
A39: =IF(A38="","",IF(A38<E8,A38+1,"")) -> 27 | B39: =IF(OR(A39="",B7=""),"",EDATE(B7,A39-1)) -> 47041 | C39: =IF(A39="","",E39-D39) -> 613.93049 | D39: =IF(A39="","",F38*E7/12) -> 177.34722 | E39: =IF(A39="","",E9) -> 791.2777 | F39: =IF(A39="","",IF(A39=E8,0,F38-C39)) -> 23058.668 | G39: =IF(A39="","",I38*Loans!C7/12) -> 9.0510345 | H39: =IF(A39="","",H9-G39) -> 634.51481 | I39: =IF(A39="","",IF(A39=E8,0,I38-H39)) -> 21087.968
A40: =IF(A39="","",IF(A39<E8,A39+1,"")) -> 28 | B40: =IF(OR(A40="",B7=""),"",EDATE(B7,A40-1)) -> 47072 | C40: =IF(A40="","",E40-D40) -> 618.52985 | D40: =IF(A40="","",F39*E7/12) -> 172.74786 | E40: =IF(A40="","",E9) -> 791.2777 | F40: =IF(A40="","",IF(A40=E8,0,F39-C40)) -> 22440.138 | G40: =IF(A40="","",I39*Loans!C7/12) -> 8.7866533 | H40: =IF(A40="","",H9-G40) -> 634.7792 | I40: =IF(A40="","",IF(A40=E8,0,I39-H40)) -> 20453.189
A41: =IF(A40="","",IF(A40<E8,A40+1,"")) -> 29 | B41: =IF(OR(A41="",B7=""),"",EDATE(B7,A41-1)) -> 47102 | C41: =IF(A41="","",E41-D41) -> 623.16367 | D41: =IF(A41="","",F40*E7/12) -> 168.11404 | E41: =IF(A41="","",E9) -> 791.2777 | F41: =IF(A41="","",IF(A41=E8,0,F40-C41)) -> 21816.975 | G41: =IF(A41="","",I40*Loans!C7/12) -> 8.522162 | H41: =IF(A41="","",H9-G41) -> 635.04369 | I41: =IF(A41="","",IF(A41=E8,0,I40-H41)) -> 19818.145
...

Sheet Referral Fees
A1: Referral Fees (engine, nothing to type)
A2: Block 1: referral fee for each payment number, Closed loans only. Fee = balance x yearly rate / 12 on a separate loan for the same Costo de Equipo and term (rate in Loans!C7). Block 2 holds that separate loan's balance.
A3: Blocks 3 and 4 (further down) turn the same fees into calendar months for the Dashboard.
A10: BLOCK 1: Referral Fee by payment number
A11: Loan # | B11: Client | C11: Status | D11: Termino (mo.) | E11: First Payment Date | F11: Costo de Equipo | G11: Referral loan monthly payment | H11: Total Referral Fee | I11: 1 | J11: 2 | K11: 3 | L11: 4 | M11: 5 | N11: 6 | O11: 7 | P11: 8 | Q11: 9 | R11: 10 | S11: 11 | T11: 12 | U11: 13 | V11: 14 | W11: 15 | X11: 16 | Y11: 17 | Z11: 18 | AA11: 19 | AB11: 20 | AC11: 21 | AD11: 22 | AE11: 23 | AF11: 24 | AG11: 25 | AH11: 26 | AI11: 27 | AJ11: 28 | AK11: 29 | AL11: 30 | AM11: 31 | AN11: 32 | AO11: 33 | AP11: 34 | AQ11: 35 | AR11: 36 | AS11: 37 | AT11: 38 | AU11: 39 | AV11: 40 | AW11: 41 | AX11: 42 | AY11: 43 | AZ11: 44 | BA11: 45 | BB11: 46 | BC11: 47 | BD11: 48 | BE11: 49 | BF11: 50 | BG11: 51 | BH11: 52 | BI11: 53 | BJ11: 54 | BK11: 55 | BL11: 56 | BM11: 57 | BN11: 58 | BO11: 59 | BP11: 60
A12: =IF(Loans!A12="","",Loans!A12) -> 1 | B12: =IF(Loans!B12="","",Loans!B12) -> SAMPLE Client A (replace) | C12: =IF(Loans!C12="","",Loans!C12) -> Closed | D12: =IF(Loans!I12="","",Loans!I12) -> 60 | E12: =IF(Loans!E12="","",Loans!E12) -> 46249 | F12: =IF(Loans!F12="","",Loans!F12) -> 38127.43 | G12: =IF(OR(C12<>"Closed",D12="",F12=""),"",PMT(Loans!C7/12,D12,-F12)) -> 643.56585 | H12: =IF(C12<>"Closed","",SUM(I12:BP12)) -> 486.52091 | I12: =IF(OR(C12<>"Closed",D12="",F12=""),"",IF(I11>D12,"",F12*Loans!C7/12)) -> 15.886429 | J12: =IF(OR(C12<>"Closed",D12="",F12=""),"",IF(J11>D12,"",I72*Loans!C7/12)) -> 15.624896 | K12: =IF(OR(C12<>"Closed",D12="",F12=""),"",IF(K11>D12,"",J72*Loans!C7/12)) -> 15.363254 | L12: =IF(OR(C12<>"Closed",D12="",F12=""),"",IF(L11>D12,"",K72*Loans!C7/12)) -> 15.101503 | M12: =IF(OR(C12<>"Closed",D12="",F12=""),"",IF(M11>D12,"",L72*Loans!C7/12)) -> 14.839643 | N12: =IF(OR(C12<>"Closed",D12="",F12=""),"",IF(N11>D12,"",M72*Loans!C7/12)) -> 14.577674 | O12: =IF(OR(C12<>"Closed",D12="",F12=""),"",IF(O11>D12,"",N72*Loans!C7/12)) -> 14.315595 | P12: =IF(OR(C12<>"Closed",D12="",F12=""),"",IF(P11>D12,"",O72*Loans!C7/12)) -> 14.053408 | Q12: =IF(OR(C12<>"Closed",D12="",F12=""),"",IF(Q11>D12,"",P72*Loans!C7/12)) -> 13.791111 | R12: =IF(OR(C12<>"Closed",D12="",F12=""),"",IF(R11>D12,"",Q72*Loans!C7/12)) -> 13.528705 | S12: =IF(OR(C12<>"Closed",D12="",F12=""),"",IF(S11>D12,"",R72*Loans!C7/12)) -> 13.266189 | T12: =IF(OR(C12<>"Closed",D12="",F12=""),"",IF(T11>D12,"",S72*Loans!C7/12)) -> 13.003564 | U12: =IF(OR(C12<>"Closed",D12="",F12=""),"",IF(U11>D12,"",T72*Loans!C7/12)) -> 12.74083 | V12: =IF(OR(C12<>"Closed",D12="",F12=""),"",IF(V11>D12,"",U72*Loans!C7/12)) -> 12.477986 | W12: =IF(OR(C12<>"Closed",D12="",F12=""),"",IF(W11>D12,"",V72*Loans!C7/12)) -> 12.215033 | X12: =IF(OR(C12<>"Closed",D12="",F12=""),"",IF(X11>D12,"",W72*Loans!C7/12)) -> 11.95197 | Y12: =IF(OR(C12<>"Closed",D12="",F12=""),"",IF(Y11>D12,"",X72*Loans!C7/12)) -> 11.688798 | Z12: =IF(OR(C12<>"Closed",D12="",F12=""),"",IF(Z11>D12,"",Y72*Loans!C7/12)) -> 11.425515 | AA12: =IF(OR(C12<>"Closed",D12="",F12=""),"",IF(AA11>D12,"",Z72*Loans!C7/12)) -> 11.162124 | AB12: =IF(OR(C12<>"Closed",D12="",F12=""),"",IF(AB11>D12,"",AA72*Loans!C7/12)) -> 10.898622 | AC12: =IF(OR(C12<>"Closed",D12="",F12=""),"",IF(AC11>D12,"",AB72*Loans!C7/12)) -> 10.635011 | AD12: =IF(OR(C12<>"Closed",D12="",F12=""),"",IF(AD11>D12,"",AC72*Loans!C7/12)) -> 10.37129 | AE12: =IF(OR(C12<>"Closed",D12="",F12=""),"",IF(AE11>D12,"",AD72*Loans!C7/12)) -> 10.107459 | AF12: =IF(OR(C12<>"Closed",D12="",F12=""),"",IF(AF11>D12,"",AE72*Loans!C7/12)) -> 9.8435175 | AG12: =IF(OR(C12<>"Closed",D12="",F12=""),"",IF(AG11>D12,"",AF72*Loans!C7/12)) -> 9.5794666 | AH12: =IF(OR(C12<>"Closed",D12="",F12=""),"",IF(AH11>D12,"",AG72*Loans!C7/12)) -> 9.3153056 | AI12: =IF(OR(C12<>"Closed",D12="",F12=""),"",IF(AI11>D12,"",AH72*Loans!C7/12)) -> 9.0510345 | AJ12: =IF(OR(C12<>"Closed",D12="",F12=""),"",IF(AJ11>D12,"",AI72*Loans!C7/12)) -> 8.7866533 | AK12: =IF(OR(C12<>"Closed",D12="",F12=""),"",IF(AK11>D12,"",AJ72*Loans!C7/12)) -> 8.522162 | AL12: =IF(OR(C12<>"Closed",D12="",F12=""),"",IF(AL11>D12,"",AK72*Loans!C7/12)) -> 8.2575605 | AM12: =IF(OR(C12<>"Closed",D12="",F12=""),"",IF(AM11>D12,"",AL72*Loans!C7/12)) -> 7.9928487 | AN12: =IF(OR(C12<>"Closed",D12="",F12=""),"",IF(AN11>D12,"",AM72*Loans!C7/12)) -> 7.7280266 | AO12: =IF(OR(C12<>"Closed",D12="",F12=""),"",IF(AO11>D12,"",AN72*Loans!C7/12)) -> 7.4630942 | AP12: =IF(OR(C12<>"Closed",D12="",F12=""),"",IF(AP11>D12,"",AO72*Loans!C7/12)) -> 7.1980514 | AQ12: =IF(OR(C12<>"Closed",D12="",F12=""),"",IF(AQ11>D12,"",AP72*Loans!C7/12)) -> 6.9328981 | AR12: =IF(OR(C12<>"Closed",D12="",F12=""),"",IF(AR11>D12,"",AQ72*Loans!C7/12)) -> 6.6676344 | AS12: =IF(OR(C12<>"Closed",D12="",F12=""),"",IF(AS11>D12,"",AR72*Loans!C7/12)) -> 6.4022601 | AT12: =IF(OR(C12<>"Closed",D12="",F12=""),"",IF(AT11>D12,"",AS72*Loans!C7/12)) -> 6.1367753 | AU12: =IF(OR(C12<>"Closed",D12="",F12=""),"",IF(AU11>D12,"",AT72*Loans!C7/12)) -> 5.8711799 | AV12: =IF(OR(C12<>"Closed",D12="",F12=""),"",IF(AV11>D12,"",AU72*Loans!C7/12)) -> 5.6054737 | AW12: =IF(OR(C12<>"Closed",D12="",F12=""),"",IF(AW11>D12,"",AV72*Loans!C7/12)) -> 5.3396569 | AX12: =IF(OR(C12<>"Closed",D12="",F12=""),"",IF(AX11>D12,"",AW72*Loans!C7/12)) -> 5.0737293 | AY12: =IF(OR(C12<>"Closed",D12="",F12=""),"",IF(AY11>D12,"",AX72*Loans!C7/12)) -> 4.807691 | AZ12: =IF(OR(C12<>"Closed",D12="",F12=""),"",IF(AZ11>D12,"",AY72*Loans!C7/12)) -> 4.5415417 | BA12: =IF(OR(C12<>"Closed",D12="",F12=""),"",IF(BA11>D12,"",AZ72*Loans!C7/12)) -> 4.2752816 | BB12: =IF(OR(C12<>"Closed",D12="",F12=""),"",IF(BB11>D12,"",BA72*Loans!C7/12)) -> 4.0089105 | BC12: =IF(OR(C12<>"Closed",D12="",F12=""),"",IF(BC11>D12,"",BB72*Loans!C7/12)) -> 3.7424285 | BD12: =IF(OR(C12<>"Closed",D12="",F12=""),"",IF(BD11>D12,"",BC72*Loans!C7/12)) -> 3.4758354 | BE12: =IF(OR(C12<>"Closed",D12="",F12=""),"",IF(BE11>D12,"",BD72*Loans!C7/12)) -> 3.2091312 | BF12: =IF(OR(C12<>"Closed",D12="",F12=""),"",IF(BF11>D12,"",BE72*Loans!C7/12)) -> 2.9423159 | BG12: =IF(OR(C12<>"Closed",D12="",F12=""),"",IF(BG11>D12,"",BF72*Loans!C7/12)) -> 2.6753894 | BH12: =IF(OR(C12<>"Closed",D12="",F12=""),"",IF(BH11>D12,"",BG72*Loans!C7/12)) -> 2.4083517 | BI12: =IF(OR(C12<>"Closed",D12="",F12=""),"",IF(BI11>D12,"",BH72*Loans!C7/12)) -> 2.1412028 | BJ12: =IF(OR(C12<>"Closed",D12="",F12=""),"",IF(BJ11>D12,"",BI72*Loans!C7/12)) -> 1.8739425 | BK12: =IF(OR(C12<>"Closed",D12="",F12=""),"",IF(BK11>D12,"",BJ72*Loans!C7/12)) -> 1.6065709 | BL12: =IF(OR(C12<>"Closed",D12="",F12=""),"",IF(BL11>D12,"",BK72*Loans!C7/12)) -> 1.3390879 | BM12: =IF(OR(C12<>"Closed",D12="",F12=""),"",IF(BM11>D12,"",BL72*Loans!C7/12)) -> 1.0714934 | BN12: =IF(OR(C12<>"Closed",D12="",F12=""),"",IF(BN11>D12,"",BM72*Loans!C7/12)) -> 0.80378739 | BO12: =IF(OR(C12<>"Closed",D12="",F12=""),"",IF(BO11>D12,"",BN72*Loans!C7/12)) -> 0.53596987 | BP12: =IF(OR(C12<>"Closed",D12="",F12=""),"",IF(BP11>D12,"",BO72*Loans!C7/12)) -> 0.26804075
A13: =IF(Loans!A13="","",Loans!A13) -> 2 | B13: =IF(Loans!B13="","",Loans!B13) -> SAMPLE Client B (replace) | C13: =IF(Loans!C13="","",Loans!C13) -> Pipeline | D13: =IF(Loans!I13="","",Loans!I13) -> 60 | E13: =IF(Loans!E13="","",Loans!E13) -> 46371 | F13: =IF(Loans!F13="","",Loans!F13) -> 58000 | G13: =IF(OR(C13<>"Closed",D13="",F13=""),"",PMT(Loans!C7/12,D13,-F13)) | H13: =IF(C13<>"Closed","",SUM(I13:BP13)) | I13: =IF(OR(C13<>"Closed",D13="",F13=""),"",IF(I11>D13,"",F13*Loans!C7/12)) | J13: =IF(OR(C13<>"Closed",D13="",F13=""),"",IF(J11>D13,"",I73*Loans!C7/12)) | K13: =IF(OR(C13<>"Closed",D13="",F13=""),"",IF(K11>D13,"",J73*Loans!C7/12)) | L13: =IF(OR(C13<>"Closed",D13="",F13=""),"",IF(L11>D13,"",K73*Loans!C7/12)) | M13: =IF(OR(C13<>"Closed",D13="",F13=""),"",IF(M11>D13,"",L73*Loans!C7/12)) | N13: =IF(OR(C13<>"Closed",D13="",F13=""),"",IF(N11>D13,"",M73*Loans!C7/12)) | O13: =IF(OR(C13<>"Closed",D13="",F13=""),"",IF(O11>D13,"",N73*Loans!C7/12)) | P13: =IF(OR(C13<>"Closed",D13="",F13=""),"",IF(P11>D13,"",O73*Loans!C7/12)) | Q13: =IF(OR(C13<>"Closed",D13="",F13=""),"",IF(Q11>D13,"",P73*Loans!C7/12)) | R13: =IF(OR(C13<>"Closed",D13="",F13=""),"",IF(R11>D13,"",Q73*Loans!C7/12)) | S13: =IF(OR(C13<>"Closed",D13="",F13=""),"",IF(S11>D13,"",R73*Loans!C7/12)) | T13: =IF(OR(C13<>"Closed",D13="",F13=""),"",IF(T11>D13,"",S73*Loans!C7/12)) | U13: =IF(OR(C13<>"Closed",D13="",F13=""),"",IF(U11>D13,"",T73*Loans!C7/12)) | V13: =IF(OR(C13<>"Closed",D13="",F13=""),"",IF(V11>D13,"",U73*Loans!C7/12)) | W13: =IF(OR(C13<>"Closed",D13="",F13=""),"",IF(W11>D13,"",V73*Loans!C7/12)) | X13: =IF(OR(C13<>"Closed",D13="",F13=""),"",IF(X11>D13,"",W73*Loans!C7/12)) | Y13: =IF(OR(C13<>"Closed",D13="",F13=""),"",IF(Y11>D13,"",X73*Loans!C7/12)) | Z13: =IF(OR(C13<>"Closed",D13="",F13=""),"",IF(Z11>D13,"",Y73*Loans!C7/12)) | AA13: =IF(OR(C13<>"Closed",D13="",F13=""),"",IF(AA11>D13,"",Z73*Loans!C7/12)) | AB13: =IF(OR(C13<>"Closed",D13="",F13=""),"",IF(AB11>D13,"",AA73*Loans!C7/12)) | AC13: =IF(OR(C13<>"Closed",D13="",F13=""),"",IF(AC11>D13,"",AB73*Loans!C7/12)) | AD13: =IF(OR(C13<>"Closed",D13="",F13=""),"",IF(AD11>D13,"",AC73*Loans!C7/12)) | AE13: =IF(OR(C13<>"Closed",D13="",F13=""),"",IF(AE11>D13,"",AD73*Loans!C7/12)) | AF13: =IF(OR(C13<>"Closed",D13="",F13=""),"",IF(AF11>D13,"",AE73*Loans!C7/12)) | AG13: =IF(OR(C13<>"Closed",D13="",F13=""),"",IF(AG11>D13,"",AF73*Loans!C7/12)) | AH13: =IF(OR(C13<>"Closed",D13="",F13=""),"",IF(AH11>D13,"",AG73*Loans!C7/12)) | AI13: =IF(OR(C13<>"Closed",D13="",F13=""),"",IF(AI11>D13,"",AH73*Loans!C7/12)) | AJ13: =IF(OR(C13<>"Closed",D13="",F13=""),"",IF(AJ11>D13,"",AI73*Loans!C7/12)) | AK13: =IF(OR(C13<>"Closed",D13="",F13=""),"",IF(AK11>D13,"",AJ73*Loans!C7/12)) | AL13: =IF(OR(C13<>"Closed",D13="",F13=""),"",IF(AL11>D13,"",AK73*Loans!C7/12)) | AM13: =IF(OR(C13<>"Closed",D13="",F13=""),"",IF(AM11>D13,"",AL73*Loans!C7/12)) | AN13: =IF(OR(C13<>"Closed",D13="",F13=""),"",IF(AN11>D13,"",AM73*Loans!C7/12)) | AO13: =IF(OR(C13<>"Closed",D13="",F13=""),"",IF(AO11>D13,"",AN73*Loans!C7/12)) | AP13: =IF(OR(C13<>"Closed",D13="",F13=""),"",IF(AP11>D13,"",AO73*Loans!C7/12)) | AQ13: =IF(OR(C13<>"Closed",D13="",F13=""),"",IF(AQ11>D13,"",AP73*Loans!C7/12)) | AR13: =IF(OR(C13<>"Closed",D13="",F13=""),"",IF(AR11>D13,"",AQ73*Loans!C7/12)) | AS13: =IF(OR(C13<>"Closed",D13="",F13=""),"",IF(AS11>D13,"",AR73*Loans!C7/12)) | AT13: =IF(OR(C13<>"Closed",D13="",F13=""),"",IF(AT11>D13,"",AS73*Loans!C7/12)) | AU13: =IF(OR(C13<>"Closed",D13="",F13=""),"",IF(AU11>D13,"",AT73*Loans!C7/12)) | AV13: =IF(OR(C13<>"Closed",D13="",F13=""),"",IF(AV11>D13,"",AU73*Loans!C7/12)) | AW13: =IF(OR(C13<>"Closed",D13="",F13=""),"",IF(AW11>D13,"",AV73*Loans!C7/12)) | AX13: =IF(OR(C13<>"Closed",D13="",F13=""),"",IF(AX11>D13,"",AW73*Loans!C7/12)) | AY13: =IF(OR(C13<>"Closed",D13="",F13=""),"",IF(AY11>D13,"",AX73*Loans!C7/12)) | AZ13: =IF(OR(C13<>"Closed",D13="",F13=""),"",IF(AZ11>D13,"",AY73*Loans!C7/12)) | BA13: =IF(OR(C13<>"Closed",D13="",F13=""),"",IF(BA11>D13,"",AZ73*Loans!C7/12)) | BB13: =IF(OR(C13<>"Closed",D13="",F13=""),"",IF(BB11>D13,"",BA73*Loans!C7/12)) | BC13: =IF(OR(C13<>"Closed",D13="",F13=""),"",IF(BC11>D13,"",BB73*Loans!C7/12)) | BD13: =IF(OR(C13<>"Closed",D13="",F13=""),"",IF(BD11>D13,"",BC73*Loans!C7/12)) | BE13: =IF(OR(C13<>"Closed",D13="",F13=""),"",IF(BE11>D13,"",BD73*Loans!C7/12)) | BF13: =IF(OR(C13<>"Closed",D13="",F13=""),"",IF(BF11>D13,"",BE73*Loans!C7/12)) | BG13: =IF(OR(C13<>"Closed",D13="",F13=""),"",IF(BG11>D13,"",BF73*Loans!C7/12)) | BH13: =IF(OR(C13<>"Closed",D13="",F13=""),"",IF(BH11>D13,"",BG73*Loans!C7/12)) | BI13: =IF(OR(C13<>"Closed",D13="",F13=""),"",IF(BI11>D13,"",BH73*Loans!C7/12)) | BJ13: =IF(OR(C13<>"Closed",D13="",F13=""),"",IF(BJ11>D13,"",BI73*Loans!C7/12)) | BK13: =IF(OR(C13<>"Closed",D13="",F13=""),"",IF(BK11>D13,"",BJ73*Loans!C7/12)) | BL13: =IF(OR(C13<>"Closed",D13="",F13=""),"",IF(BL11>D13,"",BK73*Loans!C7/12)) | BM13: =IF(OR(C13<>"Closed",D13="",F13=""),"",IF(BM11>D13,"",BL73*Loans!C7/12)) | BN13: =IF(OR(C13<>"Closed",D13="",F13=""),"",IF(BN11>D13,"",BM73*Loans!C7/12)) | BO13: =IF(OR(C13<>"Closed",D13="",F13=""),"",IF(BO11>D13,"",BN73*Loans!C7/12)) | BP13: =IF(OR(C13<>"Closed",D13="",F13=""),"",IF(BP11>D13,"",BO73*Loans!C7/12))
